Workbook
Name Band_of_Investment_Assumptions: BOI!$H$2:$J$8
Name DSCR: BOI!$V$3:$Y$4
Name Income_Proforma: BOI!$B$2:$F$14
Name Mortgage_Equity_CapRate: BOI!$L$3:$R$6

Sheet Subj.
B3: NOTE the *'s are id's in the doc
B4: *es_property_info
B5: TVAS File No. | D5: 22061
B6: Property Type(s) | D6: General Purpose Warehouse
B7: Property Subtypes(s) | D7: Bulk Warehouse
B8: Property Address | D8: 4735 Dwight Evans Rd
D9: Charlotte, NC
B10: Zip Code | D10: 28217
B11: Parcel No(s) | D11: 145-301-22
B12: County | D12: Mecklenburg
B13: *es_property_history
B14: Current Owner(s) | D14: Investicore Prop Co 9, LLC | E14: LLC in sep tag in word
B15: Previous Market Sale | D15: 44153
B16: Previous Sale Price | D16: 1360000
B17: Previous Debt | D17: 884000 | G17: some of these values are not made it to Word
B18: Lender | D18: Stormfield Cap Funding I, LLC
B19: Previous Owner | D19: Park Avenue Partners, LLC
B20: Property Status | D20: Pending Sale
B21: *es_site_characteristics
B22: Total Land Area | D22: 2.59
D23: =D22*43560 -> 112820.4
B24: Frontage | D24: 265.77
B25: Site Shape | D25: Irregular
B26: Site Utility | D26: Average
B27: Topography | D27: Gently Sloping
B28: Current Zoning | D28: I-2
D29: Heavy Industrial District
B30: Zoning Jursdiction | D30: Charlotte
B31: Utilities | D31: All Available
B32: No. of Stories | D32: One
B33: *es_improvements
B34: Construction Class | D34: Class S, Structural Steel-Frame
B35: Construction Quality | D35: Average
B36: Year(s) Built | D36: 1989
B37: Gross Building Area (SF) | D37: 16268
B38: Rentable Building Area (SF) | D38: 16268
B39: Total Condo GBA (SF) | D39: 57780
B40: Mezzanine (SF) | D40: None
B41: Finished Office Area | D41: 1209
B42: Finished Ratio | D42: =D41/D37 -> 0.074317679
...

Sheet SSum
A1: Sale | B1: Address | C1: City | D1: Parcel No.(s) | E1: Date of Sale | F1: Sale Price | G1: Price/SF | H1: Grantor | I1: Grantee | J1: Property Rights | K1: Occupancy ATOS | L1: Verification | M1: Gross Building Area (SF) | N1: Year Built | O1: Site Size (SF) | P1: Coverage Ratio | Q1: Office (SF) | R1: Office Ratio | S1: Quality | T1: Effective Age/Condition | U1: Eave Height | V1: Access | W1: Parking Spaces | X1: Parking Ratio | Y1: Building Use | Z1: Loading | AA1: Loading SF | AB1: Other | AC1: Zoning | AD1: Comments | AE1: Notes | AF1: FAR | AG1: Price/Lot
A3: Subject | B3: =Subj.!D8 -> 4735 Dwight Evans Rd | C3: =Subj.!D9 -> Charlotte, NC | D3: =Subj.!D11 -> 145-301-22 | M3: =Subj.!D37 -> 16268 | N3: =Subj.!D36 -> 1989 | O3: =Subj.!D23 -> 112820.4 | P3: =Subj.!D43 -> 0.51214142 | Q3: =Subj.!D41 -> 1209 | R3: =Subj.!D42 -> 0.074317679 | S3: =Subj.!D35 -> Average | T3: =Subj.!D54 -> 10 | U3: =Subj.!D44 -> 18 | V3: =Subj.!D58 -> Good | W3: =Subj.!D50 -> 53 | X3: =Subj.!D51 -> 0.91727241 | Y3: Industrial | Z3: =Subj.!D47 -> 0 GL/3 DH | AA3: =Subj.!D48 -> 5422.6667 | AB3: None | AC3: =Subj.!D28 -> I-2 | AF3: =M3/O3 -> 0.14419378
B6: 10725 John Price Rd | C6: Charlotte, NC | D6: 201-181-27 | E6: 44698 | F6: 2275000 | G6: =F6/M6 -> 115.98858 | H6: MSE Center LLC | I6: Sand Fiddlers Partners, LLC | J6: Leased Fee | K6: 0.5 | L6: Listing Broker | M6: 19614 | N6: 1988 | O6: 60984 | P6: =M6/O6 -> 0.32162534 | Q6: 4412 | R6: =Q6/M6 -> 0.22494137 | S6: Average | T6: 10 | U6: 20 | V6: Good | W6: 29 | X6: =W6/(M6/1000) -> 1.4785357 | Y6: Industrial | Z6: 1 GL/3 DH | AA6: =M6/4 -> 4903.5 | AB6: None | AD6: The sale of a freestanding, multi-tenant industrial building located on the southeast side of John Price Road just north of South Tryon Street and about two miles southwest of the Interstate 485/South Tryon Street interchange within the city limits of Charlotte. The building was constructed in 1988 and features concrete block construction, wet sprinkler system and a clear height of 20'. The two-suite building was 50 percent occupied at the time of sale with the tenant leased through August 2026. The property was on the market for about nine months with an original asking price of $2,300,000. Truist Bank financed the deal with a loan in the amount of $1,955,000.
B7: 1508 Industrial Dr | C7: Matthews, NC | D7: 193-211-07 | E7: 44547 | F7: 1845000 | G7: =F7/M7 -> 143.69159 | H7: Match Properties, LLC | I7: Wilkat, LLC | J7: Fee Simple | K7: Vacant | L7: Listing Broker | M7: 12840 | N7: 1986 | O7: 105981 | P7: =M7/O7 -> 0.12115379 | Q7: 3500 | R7: =Q7/M7 -> 0.27258567 | S7: Average | T7: 10 | U7: 18 | V7: Good | W7: 10 | X7: =W7/(M7/1000) -> 0.7788162 | Y7: Industrial | Z7: 1 GL/2 DH | AA7: =M7/3 -> 4280 | AB7: None | AD7: The sale of a freestanding industrial building located approximately one mile northwest of the intersection of U.S. Highway 74 and N.C. Highway 51 within the Town of Matthews in Mecklenburg County, North Carolina. The building was constructed in 1986 and features a structural-steel spanning system with a clear height of 18'. The property was on the market for about a month with an asking price of $1,875,000. The building is currently owner-occupied by a foundation repair company dba Cantey Foundation Specialists. First Palmetto Bank financed the deal with a loan in the amount of $1,800,000.
B8: 138 Cedar Pointe Dr | C8: Mooresville, NC | D8: 4648-90-4665.000 | E8: 43976 | F8: 1575000 | G8: =F8/M8 -> 103.61842 | H8: D&G Realty, LLC | I8: 138 Cedar Pointe, LLC | J8: Fee Simple | K8: Vacant | L8: Listing Broker | M8: 15200 | N8: 2001 | O8: 60113 | P8: =M8/O8 -> 0.25285712 | Q8: 4200 | R8: =Q8/M8 -> 0.27631579 | S8: Average | T8: 10 | U8: 18 | V8: Good | W8: 33 | X8: =W8/(M8/1000) -> 2.1710526 | Y8: Industrial | Z8: 3 GL/1 DH | AA8: =M8/4 -> 3800 | AB8: None | AD8: The sale of an industrial flex building located on the east side of Cedar Pointe Drive just east of Interstate 77 within the city limits of Mooresville in Iredell County, North Carolina. The property is currently owner-occupied dba Tiger Precision Products. This is believed to be an all-cash sale. | AF8: =M8/O8 -> 0.25285712 | AG8: =F8/O8 -> 26.200655
B9: 227 Old Hebron St | C9: Charlotte, NC | D9: 205-171-24 | E9: 44119 | F9: 1725000 | G9: =F9/M9 -> 134.01181 | H9: OHR Properties, LLC | I9: Hop Holdings, LLC | J9: Fee Simple | K9: Vacant | L9: Listing Broker | M9: 12872 | N9: 1989 | O9: 87120 | P9: =M9/O9 -> 0.14775023 | Q9: 3988 | R9: =Q9/M9 -> 0.30981976 | S9: Average | T9: 10 | U9: 21 | V9: Good | W9: 14 | X9: =W9/(M9/1000) -> 1.0876321 | Y9: Industrial | Z9: 1 GL/2 DH | AA9: =M9/3 -> 4290.6667 | AB9: Ancillary Bldg. | AD9: The sale of an industrial flex building located on the north side of Old Hebron Road within the city limits of Charlotte in Mecklenburg County, North Carolina. The site slopes downward from the road frontage which provides for terrace-level, climate-controlled storage below the office portion of the building. The property is also improved with a 2,294-sf ancillary industrial building with two grade-level doors. West Town Bank & Trust financed the deal with a loan in the amount of $1,705,200. | AF9: =M9/O9 -> 0.14775023 | AG9: =F9/O9 -> 19.800275
B10: 1020 Forsyth Ave | C10: Indian Trail, NC | D10: 07-081-303 | E10: 43977 | F10: 1775000 | G10: =F10/M10 -> 123.26389 | H10: Pierson Enterprises, LLC | I10: Oakway Properties, LLC | J10: Leased Fee | K10: 0.67 | L10: Listing Broker | M10: 14400 | N10: 2008 | O10: 100624 | P10: =M10/O10 -> 0.14310701 | Q10: 7146 | R10: =Q10/M10 -> 0.49625 | S10: Average | T10: 5 | U10: 18 | V10: Good | W10: 28 | X10: =W10/(M10/1000) -> 1.9444444 | Y10: Industrial | Z10: 3 GL/2 DH | AA10: =M10/5 -> 2880 | AB10: None | AD10: The sale of a multi-tenant industrial flex building located in Old Hickory Business Park just northeast of East Independence Boulevard within the town limits of Indian Trail in Union County, North Carolina. At the time of sale, two of the three suites were tenant-occupied. South State Bank financed the deal with a seven-year note in the amount of $1,500,000. | AF10: =M10/O10 -> 0.14310701 | AG10: =F10/O10 -> 17.639927
A13: Farm List
B15: 205 Raceway Dr | C15: Mooresville, NC | D15: 4647-44-8341.000 | E15: 44236 | F15: 1225000 | G15: =F15/M15 -> 92.80303 | H15: Zip Properties, Inc. | I15: HSUS Investments, LLC | J15: Leased Fee | K15: 0.32 | L15: Listing Broker | M15: 13200 | N15: 1999 | O15: 43560 | P15: =M15/O15 -> 0.3030303 | Q15: 4875 | R15: =Q15/M15 -> 0.36931818 | S15: Very Good | T15: 5 | U15: 18 | V15: Average | W15: 18 | X15: =W15/(M15/1000) -> 1.3636364 | Y15: Industrial Flex | Z15: 6 GL/0 DH | AA15: =M15/6 -> 2200 | AB15: None | AC15: HI | AD15: The sale of a multi-tenant industrial flex building located on the northeast side of Raceway Drive just west of Interstate 77 within the city limits of Mooresville in Iredell County, North Carolina. At the time of sale, the building consisted of two tenant-occupied suites and a 9,000-sf vacant third suite. The vacant suite is currently marketed for lease with an asking rental rate of $7.00 psf on a triple-net basis. Horizon Bank financed the deal with a ten-year note in the amount of $1,100,000. | AF15: =M15/O15 -> 0.3030303 | AG15: =F15/O15 -> 28.12213
B16: 635 Southwest St | C16: High Point, NC | D16: 178454 | E16: 44376 | F16: 1050000 | G16: =F16/M16 -> 87.5 | H16: Confidence Containers, LLC | I16: Brock & Connie Baird | J16: Fee Simple | K16: 1 | L16: Listing Broker | M16: 12000 | N16: 1989 | O16: 63598 | P16: =M16/O16 -> 0.18868518 | Q16: 2000 | R16: =Q16/M16 -> 0.16666667 | S16: Average + | T16: 5 | U16: 15 | V16: Average | W16: 21 | X16: =W16/(M16/1000) -> 1.75 | Y16: Industrial Flex | Z16: 1 GL/4 DH | AA16: =M16/5 -> 2400 | AB16: None | AD16: The sale of an industrial warehouse building located on the east side of Southwest Street within the city limits of High Point in Guilford County, North Carolina. The property is currently offered for lease with an asking rental rate of $6.50 psf on a triple-net lease basis. This is believed to be an all-cash sale. | AF16: =M16/O16 -> 0.18868518 | AG16: =F16/O16 -> 16.509953

Sheet S1
A1: Comparable Sale 1 | B1: =SG!#REF! -> #REF!
A2: Location Details
A3: =SSum!B1 -> Address | B3: =SSum!B6 -> 10725 John Price Rd
B4: =SSum!C6 -> Charlotte, NC
A5: =SSum!D1 -> Parcel No.(s) | B5: =SSum!D6 -> 201-181-27
A6: Transaction Data
A7: =SSum!E1 -> Date of Sale | B7: =SSum!E6 -> 44698
A8: =SSum!F1 -> Sale Price | B8: =SSum!F6 -> 2275000
A9: =SSum!G1 -> Price/SF | B9: =SSum!G6 -> 115.98858
A10: =SSum!H1 -> Grantor | B10: =SSum!H6 -> MSE Center LLC
A11: =SSum!I1 -> Grantee | B11: =SSum!I6 -> Sand Fiddlers Partners, LLC
A12: =SSum!J1 -> Property Rights | B12: =SSum!J6 -> Leased Fee
A13: =SSum!K1 -> Occupancy ATOS | B13: =SSum!K6 -> 0.5
A14: =SSum!L1 -> Verification | B14: =SSum!L6 -> Listing Broker
A15: Physical Attributes
A16: =SSum!M1 -> Gross Building Area (SF) | B16: =SSum!M6 -> 19614
A17: =SSum!N1 -> Year Built | B17: =SSum!N6 -> 1988
A18: =SSum!O1 -> Site Size (SF) | B18: =SSum!O6 -> 60984
A19: Coverage Ratio | B19: =SSum!P6 -> 0.32162534
A20: =SSum!R1 -> Office Ratio | B20: =SSum!R6 -> 0.22494137
A21: =SSum!S1 -> Quality | B21: =SSum!S6 -> Average
A22: =SSum!T1 -> Effective Age/Condition | B22: =SSum!T6 -> 10
A23: =SSum!V1 -> Access | B23: =SSum!V6 -> Good
A24: =SSum!X1 -> Parking Ratio | B24: =SSum!X6 -> 1.4785357
A25: =SSum!Y1 -> Building Use | B25: =SSum!Y6 -> Industrial
A26: =SSum!U1 -> Eave Height | B26: =SSum!U6 -> 20
A27: =SSum!Z1 -> Loading | B27: =SSum!Z6 -> 1 GL/3 DH
A28: =SSum!AA1 -> Loading SF | B28: =SSum!AA6 -> 4903.5
A29: Comments
A30: =SSum!AD6 -> The sale of a freestanding, multi-tenant industrial building located on the southeast side of John Price Road just north of South Tryon Street and about two miles southwest of the Interstate 485/South Tryon Street interchange within the city limits of Charlotte. The building was constructed in 1988 and features concrete block construction, wet sprinkler system and a clear height of 20'. The two-suite building was 50 percent occupied at the time of sale with the tenant leased through August 2026. The property was on the market for about nine months with an original asking price of $2,300,000. Truist Bank financed the deal with a loan in the amount of $1,955,000. | B30: #REF!

Sheet S2
A1: Comparable Sale 2
A2: Location Details
A3: =SSum!B1 -> Address | B3: =SSum!B7 -> 1508 Industrial Dr
B4: =SSum!C7 -> Matthews, NC
A5: =SSum!D1 -> Parcel No.(s) | B5: =SSum!D7 -> 193-211-07
A6: Transaction Data
A7: =SSum!E1 -> Date of Sale | B7: =SSum!E7 -> 44547
A8: =SSum!F1 -> Sale Price | B8: =SSum!F7 -> 1845000
A9: =SSum!G1 -> Price/SF | B9: =SSum!G7 -> 143.69159
A10: =SSum!H1 -> Grantor | B10: =SSum!H7 -> Match Properties, LLC
A11: =SSum!I1 -> Grantee | B11: =SSum!I7 -> Wilkat, LLC
A12: =SSum!J1 -> Property Rights | B12: =SSum!J7 -> Fee Simple
A13: =SSum!K1 -> Occupancy ATOS | B13: =SSum!K7 -> Vacant
A14: =SSum!L1 -> Verification | B14: =SSum!L7 -> Listing Broker
A15: Physical Attributes
A16: =SSum!M1 -> Gross Building Area (SF) | B16: =SSum!M7 -> 12840
A17: =SSum!N1 -> Year Built | B17: =SSum!N7 -> 1986
A18: =SSum!O1 -> Site Size (SF) | B18: =SSum!O7 -> 105981
A19: Coverage Ratio | B19: =SSum!P7 -> 0.12115379
A20: =SSum!R1 -> Office Ratio | B20: =SSum!R7 -> 0.27258567
A21: =SSum!S1 -> Quality | B21: =SSum!S7 -> Average
A22: =SSum!T1 -> Effective Age/Condition | B22: =SSum!T7 -> 10
A23: =SSum!V1 -> Access | B23: =SSum!V7 -> Good
A24: =SSum!X1 -> Parking Ratio | B24: =SSum!X7 -> 0.7788162
A25: =SSum!Y1 -> Building Use | B25: =SSum!Y7 -> Industrial
A26: =SSum!U1 -> Eave Height | B26: =SSum!U7 -> 18
A27: =SSum!Z1 -> Loading | B27: =SSum!Z7 -> 1 GL/2 DH
A28: =SSum!AA1 -> Loading SF | B28: =SSum!AA7 -> 4280
A29: Comments
A30: =SSum!AD7 -> The sale of a freestanding industrial building located approximately one mile northwest of the intersection of U.S. Highway 74 and N.C. Highway 51 within the Town of Matthews in Mecklenburg County, North Carolina. The building was constructed in 1986 and features a structural-steel spanning system with a clear height of 18'. The property was on the market for about a month with an asking price of $1,875,000. The building is currently owner-occupied by a foundation repair company dba Cantey Foundation Specialists. First Palmetto Bank financed the deal with a loan in the amount of $1,800,000.

Sheet S3
A1: Comparable Sale 3 | B1: =SG!#REF! -> #REF!
A2: Location Details
A3: =SSum!B1 -> Address | B3: =SSum!B8 -> 138 Cedar Pointe Dr
B4: =SSum!C8 -> Mooresville, NC
A5: =SSum!D1 -> Parcel No.(s) | B5: =SSum!D8 -> 4648-90-4665.000
A6: Transaction Data
A7: =SSum!E1 -> Date of Sale | B7: =SSum!E8 -> 43976
A8: =SSum!F1 -> Sale Price | B8: =SSum!F8 -> 1575000
A9: =SSum!G1 -> Price/SF | B9: =SSum!G8 -> 103.61842
A10: =SSum!H1 -> Grantor | B10: =SSum!H8 -> D&G Realty, LLC
A11: =SSum!I1 -> Grantee | B11: =SSum!I8 -> 138 Cedar Pointe, LLC
A12: =SSum!J1 -> Property Rights | B12: =SSum!J8 -> Fee Simple
A13: =SSum!K1 -> Occupancy ATOS | B13: =SSum!K8 -> Vacant
A14: =SSum!L1 -> Verification | B14: =SSum!L8 -> Listing Broker
A15: Physical Attributes
A16: =SSum!M1 -> Gross Building Area (SF) | B16: =SSum!M8 -> 15200
A17: =SSum!N1 -> Year Built | B17: =SSum!N8 -> 2001
A18: =SSum!O1 -> Site Size (SF) | B18: =SSum!O8 -> 60113
A19: Coverage Ratio | B19: =SSum!P8 -> 0.25285712
A20: =SSum!R1 -> Office Ratio | B20: =SSum!R8 -> 0.27631579
A21: =SSum!S1 -> Quality | B21: =SSum!S8 -> Average
A22: =SSum!T1 -> Effective Age/Condition | B22: =SSum!T8 -> 10
A23: =SSum!V1 -> Access | B23: =SSum!V8 -> Good
A24: =SSum!X1 -> Parking Ratio | B24: =SSum!X8 -> 2.1710526
A25: =SSum!Y1 -> Building Use | B25: =SSum!Y8 -> Industrial
A26: =SSum!U1 -> Eave Height | B26: =SSum!U8 -> 18
A27: =SSum!Z1 -> Loading | B27: =SSum!Z8 -> 3 GL/1 DH
A28: =SSum!AA1 -> Loading SF | B28: =SSum!AA8 -> 3800
A29: Comments
A30: =SSum!AD8 -> The sale of an industrial flex building located on the east side of Cedar Pointe Drive just east of Interstate 77 within the city limits of Mooresville in Iredell County, North Carolina. The property is currently owner-occupied dba Tiger Precision Products. This is believed to be an all-cash sale.

Sheet S4
A1: Comparable Sale 4 | B1: =SG!#REF! -> #REF!
A2: Location Details
A3: =SSum!B1 -> Address | B3: =SSum!B9 -> 227 Old Hebron St
B4: =SSum!C9 -> Charlotte, NC
A5: =SSum!D1 -> Parcel No.(s) | B5: =SSum!D9 -> 205-171-24
A6: Transaction Data
A7: =SSum!E1 -> Date of Sale | B7: =SSum!E9 -> 44119
A8: =SSum!F1 -> Sale Price | B8: =SSum!F9 -> 1725000
A9: =SSum!G1 -> Price/SF | B9: =SSum!G9 -> 134.01181
A10: =SSum!H1 -> Grantor | B10: =SSum!H9 -> OHR Properties, LLC
A11: =SSum!I1 -> Grantee | B11: =SSum!I9 -> Hop Holdings, LLC
A12: =SSum!J1 -> Property Rights | B12: =SSum!J9 -> Fee Simple
A13: =SSum!K1 -> Occupancy ATOS | B13: =SSum!K9 -> Vacant
A14: =SSum!L1 -> Verification | B14: =SSum!L9 -> Listing Broker
A15: Physical Attributes
A16: =SSum!M1 -> Gross Building Area (SF) | B16: =SSum!M9 -> 12872
A17: =SSum!N1 -> Year Built | B17: =SSum!N9 -> 1989
A18: =SSum!O1 -> Site Size (SF) | B18: =SSum!O9 -> 87120
A19: Coverage Ratio | B19: =SSum!P9 -> 0.14775023
A20: =SSum!R1 -> Office Ratio | B20: =SSum!R9 -> 0.30981976
A21: =SSum!S1 -> Quality | B21: =SSum!S9 -> Average
A22: =SSum!T1 -> Effective Age/Condition | B22: =SSum!T9 -> 10
A23: =SSum!V1 -> Access | B23: =SSum!V9 -> Good
A24: =SSum!X1 -> Parking Ratio | B24: =SSum!X9 -> 1.0876321
A25: =SSum!Y1 -> Building Use | B25: =SSum!Y9 -> Industrial
A26: =SSum!U1 -> Eave Height | B26: =SSum!U9 -> 21
A27: =SSum!Z1 -> Loading | B27: =SSum!Z9 -> 1 GL/2 DH
A28: =SSum!AA1 -> Loading SF | B28: =SSum!AA9 -> 4290.6667
A29: Comments
A30: =SSum!AD9 -> The sale of an industrial flex building located on the north side of Old Hebron Road within the city limits of Charlotte in Mecklenburg County, North Carolina. The site slopes downward from the road frontage which provides for terrace-level, climate-controlled storage below the office portion of the building. The property is also improved with a 2,294-sf ancillary industrial building with two grade-level doors. West Town Bank & Trust financed the deal with a loan in the amount of $1,705,200.

Sheet S5
A1: Comparable Sale 5 | B1: =SG!#REF! -> #REF!
A2: Location Details
A3: =SSum!B1 -> Address | B3: =SSum!B10 -> 1020 Forsyth Ave
B4: =SSum!C10 -> Indian Trail, NC
A5: =SSum!D1 -> Parcel No.(s) | B5: =SSum!D10 -> 07-081-303
A6: Transaction Data
A7: =SSum!E1 -> Date of Sale | B7: =SSum!E10 -> 43977
A8: =SSum!F1 -> Sale Price | B8: =SSum!F10 -> 1775000 | K8: A
A9: =SSum!G1 -> Price/SF | B9: =SSum!G10 -> 123.26389
A10: =SSum!H1 -> Grantor | B10: =SSum!H10 -> Pierson Enterprises, LLC
A11: =SSum!I1 -> Grantee | B11: =SSum!I10 -> Oakway Properties, LLC
A12: =SSum!J1 -> Property Rights | B12: =SSum!J10 -> Leased Fee
A13: =SSum!K1 -> Occupancy ATOS | B13: =SSum!K10 -> 0.67
A14: =SSum!L1 -> Verification | B14: =SSum!L10 -> Listing Broker
A15: Physical Attributes
A16: =SSum!M1 -> Gross Building Area (SF) | B16: =SSum!M10 -> 14400
A17: =SSum!N1 -> Year Built | B17: =SSum!N10 -> 2008
A18: =SSum!O1 -> Site Size (SF) | B18: =SSum!O10 -> 100624
A19: Coverage Ratio | B19: =SSum!P10 -> 0.14310701
A20: =SSum!R1 -> Office Ratio | B20: =SSum!R10 -> 0.49625
A21: =SSum!S1 -> Quality | B21: =SSum!S10 -> Average
A22: =SSum!T1 -> Effective Age/Condition | B22: =SSum!T10 -> 5
A23: =SSum!V1 -> Access | B23: =SSum!V10 -> Good
A24: =SSum!X1 -> Parking Ratio | B24: =SSum!X10 -> 1.9444444
A25: =SSum!Y1 -> Building Use | B25: =SSum!Y10 -> Industrial
A26: =SSum!U1 -> Eave Height | B26: =SSum!U10 -> 18
A27: =SSum!Z1 -> Loading | B27: =SSum!Z10 -> 3 GL/2 DH
A28: =SSum!AA1 -> Loading SF | B28: =SSum!AA10 -> 2880
A29: Comments
A30: =SSum!AD10 -> The sale of a multi-tenant industrial flex building located in Old Hickory Business Park just northeast of East Independence Boulevard within the town limits of Indian Trail in Union County, North Carolina. At the time of sale, two of the three suites were tenant-occupied. South State Bank financed the deal with a seven-year note in the amount of $1,500,000.

Sheet SAdj
A2: Row Height: 17
A4: Subject | B4: =SG!C35 -> 16268 | E4: Gross Building Area (SF) | F4: Difference (SF) | G4: Applied Adjustment | I4: Comparable Sale | J4: 1 | K4: 2 | L4: 3 | M4: 4 | N4: 5
A5: Base | B5: 0.05 | D5: Sale 1 | E5: =SG!D35 -> 19614 | F5: =ABS(E5-$B$4) -> 3346 | G5: =B5 -> 0.05 | I5: Office Differential (SF)* | J5: =(SG!$C$20-SG!D20)*SG!D16 -> -2954.333 | K5: =(SG!$C$20-SG!E20)*SG!E16 -> -2545.761 | L5: =(SG!$C$20-SG!F20)*SG!F16 -> -3070.3713 | M5: =(SG!$C$20-SG!G20)*SG!G16 -> -3031.3828 | N5: =(SG!$C$20-SG!H20)*SG!H16 -> -6075.8254
D6: Subject | E6: =SG!C35 -> 16268 | F6: - | G6: - | I6: Contributory Value $15/SF | J6: =J5*15 -> -44314.996 | K6: =K5*15 -> -38186.415 | L6: =L5*15 -> -46055.569 | M6: =M5*15 -> -45470.743 | N6: =N5*15 -> -91137.381
D7: Sale 3 | E7: =SG!F35 -> 15200 | F7: =ABS(E7-$B$4) -> 1068 | G7: =F7/F5*B5*-1 -> -0.015959354 | I7: Sale Price | J7: =SG!D8 -> 2275000 | K7: =SG!E8 -> 1845000 | L7: =SG!F8 -> 1575000 | M7: =SG!G8 -> 1725000 | N7: =SG!H8 -> 1775000
D8: Sale 5 | E8: =SG!H35 -> 14400 | F8: =ABS(E8-$B$4) -> 1868 | G8: =F8/F5*B5*-1 -> -0.027913927 | I8: Implied Adjustment | J8: =J6/J7 -> -0.019479119 | K8: =K6/K7 -> -0.020697244 | L8: =L6/L7 -> -0.029241631 | M8: =M6/M7 -> -0.026359851 | N8: =N6/N7 -> -0.051345004
D9: Sale 4 | E9: =SG!G35 -> 12872 | F9: =ABS(E9-$B$4) -> 3396 | G9: =F9/F5*B5*-1 -> -0.050747161
D10: Sale 2 | E10: =SG!E35 -> 12840 | F10: =ABS(E10-$B$4) -> 3428 | G10: =F10/F5*B5*-1 -> -0.051225344
I12: Comparable Sale | J12: 1 | K12: 2 | L12: 3 | M12: 4 | N12: 5
I13: Height Differential (Feet) | J13: =SG!$C$25-SG!D25 -> -2 | K13: =SG!$C$25-SG!E25 -> 0 | L13: =SG!$C$25-SG!F25 -> 0 | M13: =SG!$C$25-SG!G25 -> -3 | N13: =SG!$C$25-SG!H25 -> 0
I14: Contributory Value @ $0.71/LF x Bldg. SF | J14: =0.71*ABS(J13)*SG!D16 -> 27851.88 | K14: =0.71*ABS(K13)*SG!E16 -> 0 | L14: =0.71*ABS(L13)*SG!F16 -> 0 | M14: =0.71*ABS(M13)*SG!G16 -> 27417.36 | N14: =0.71*ABS(N13)*SG!H16 -> 0
I15: Sale Price | J15: =SG!D8 -> 2275000 | K15: =SG!E8 -> 1845000 | L15: =SG!F8 -> 1575000 | M15: =SG!G8 -> 1725000 | N15: =SG!H8 -> 1775000
I16: Implied Adjustment | J16: =J14/J15*-1 -> -0.012242585 | K16: =K14/K15*-1 -> 0 | L16: =L14/L15*-1 -> 0 | M16: =M14/M15*-1 -> -0.015894122 | N16: =N14/N15 -> 0

Sheet SG
C1: Subject | D1: Sale 1 | E1: Sale 2 | F1: Sale 3 | G1: Sale 4 | H1: Sale 5
B2: Location Details
B3: Address | C3: =SSum!B3 -> 4735 Dwight Evans Rd | D3: ='S1'!B3 -> 10725 John Price Rd | E3: ='S2'!B3 -> 1508 Industrial Dr | F3: ='S3'!B3 -> 138 Cedar Pointe Dr | G3: ='S4'!B3 -> 227 Old Hebron St | H3: ='S5'!B3 -> 1020 Forsyth Ave
C4: =SSum!C3 -> Charlotte, NC | D4: ='S1'!B4 -> Charlotte, NC | E4: ='S2'!B4 -> Matthews, NC | F4: ='S3'!B4 -> Mooresville, NC | G4: ='S4'!B4 -> Charlotte, NC | H4: ='S5'!B4 -> Indian Trail, NC
B5: Parcel No.(s) | C5: =SSum!D3 -> 145-301-22 | D5: ='S1'!B5 -> 201-181-27 | E5: ='S2'!B5 -> 193-211-07 | F5: ='S3'!B5 -> 4648-90-4665.000 | G5: ='S4'!B5 -> 205-171-24 | H5: ='S5'!B5 -> 07-081-303
B6: Transaction Data
B7: Date of Sale | D7: ='S1'!B7 -> 44698 | E7: ='S2'!B7 -> 44547 | F7: ='S3'!B7 -> 43976 | G7: ='S4'!B7 -> 44119 | H7: ='S5'!B7 -> 43977
B8: Sale Price | D8: ='S1'!B8 -> 2275000 | E8: ='S2'!B8 -> 1845000 | F8: ='S3'!B8 -> 1575000 | G8: ='S4'!B8 -> 1725000 | H8: ='S5'!B8 -> 1775000
B9: Price/SF | D9: ='S1'!B9 -> 115.98858 | E9: ='S2'!B9 -> 143.69159 | F9: ='S3'!B9 -> 103.61842 | G9: ='S4'!B9 -> 134.01181 | H9: ='S5'!B9 -> 123.26389
B10: Grantor | D10: ='S1'!B10 -> MSE Center LLC | E10: ='S2'!B10 -> Match Properties, LLC | F10: ='S3'!B10 -> D&G Realty, LLC | G10: ='S4'!B10 -> OHR Properties, LLC | H10: ='S5'!B10 -> Pierson Enterprises, LLC
B11: Grantee | D11: ='S1'!B11 -> Sand Fiddlers Partners, LLC | E11: ='S2'!B11 -> Wilkat, LLC | F11: ='S3'!B11 -> 138 Cedar Pointe, LLC | G11: ='S4'!B11 -> Hop Holdings, LLC | H11: ='S5'!B11 -> Oakway Properties, LLC
B12: Property Rights | D12: ='S1'!B12 -> Leased Fee | E12: ='S2'!B12 -> Fee Simple | F12: ='S3'!B12 -> Fee Simple | G12: ='S4'!B12 -> Fee Simple | H12: ='S5'!B12 -> Leased Fee
B13: Occupancy ATOS | D13: ='S1'!B13 -> 0.5 | E13: ='S2'!B13 -> Vacant | F13: ='S3'!B13 -> Vacant | G13: ='S4'!B13 -> Vacant | H13: ='S5'!B13 -> 0.67
B14: Verification | D14: ='S1'!B14 -> Listing Broker | E14: ='S2'!B14 -> Listing Broker | F14: ='S3'!B14 -> Listing Broker | G14: ='S4'!B14 -> Listing Broker | H14: ='S5'!B14 -> Listing Broker
B15: Physical Attributes
B16: =SSum!M1 -> Gross Building Area (SF) | C16: =SSum!M3 -> 16268 | D16: ='S1'!B16 -> 19614 | E16: ='S2'!B16 -> 12840 | F16: ='S3'!B16 -> 15200 | G16: ='S4'!B16 -> 12872 | H16: ='S5'!B16 -> 14400 | J16: new const. or sales/inc not good ..
B17: =SSum!N1 -> Year Built | C17: =SSum!N3 -> 1989 | D17: ='S1'!B17 -> 1988 | E17: ='S2'!B17 -> 1986 | F17: ='S3'!B17 -> 2001 | G17: ='S4'!B17 -> 1989 | H17: ='S5'!B17 -> 2008
B18: =SSum!O1 -> Site Size (SF) | C18: =SSum!O3 -> 112820.4 | D18: ='S1'!B18 -> 60984 | E18: ='S2'!B18 -> 105981 | F18: ='S3'!B18 -> 60113 | G18: ='S4'!B18 -> 87120 | H18: ='S5'!B18 -> 100624
B19: Coverage Ratio | C19: =SSum!P3 -> 0.51214142 | D19: =SSum!P6 -> 0.32162534 | E19: =SSum!P7 -> 0.12115379 | F19: =SSum!P8 -> 0.25285712 | G19: =SSum!P9 -> 0.14775023 | H19: =SSum!P10 -> 0.14310701
B20: =SSum!R1 -> Office Ratio | C20: =SSum!R3 -> 0.074317679 | D20: ='S1'!B20 -> 0.22494137 | E20: ='S2'!B20 -> 0.27258567 | F20: ='S3'!B20 -> 0.27631579 | G20: ='S4'!B20 -> 0.30981976 | H20: ='S5'!B20 -> 0.49625
B21: =SSum!S1 -> Quality | C21: =SSum!S3 -> Average | D21: ='S1'!B21 -> Average | E21: ='S2'!B21 -> Average | F21: ='S3'!B21 -> Average | G21: ='S4'!B21 -> Average | H21: ='S5'!B21 -> Average
B22: =SSum!T1 -> Effective Age/Condition | C22: =SSum!T3 -> 10 | D22: ='S1'!B22 -> 10 | E22: ='S2'!B22 -> 10 | F22: ='S3'!B22 -> 10 | G22: ='S4'!B22 -> 10 | H22: ='S5'!B22 -> 5
B23: =SSum!V1 -> Access | C23: =SSum!V3 -> Good | D23: ='S1'!B23 -> Good | E23: ='S2'!B23 -> Good | F23: ='S3'!B23 -> Good | G23: ='S4'!B23 -> Good | H23: ='S5'!B23 -> Good
B24: =SSum!X1 -> Parking Ratio | C24: =SSum!X3 -> 0.91727241 | D24: ='S1'!B24 -> 1.4785357 | E24: ='S2'!B24 -> 0.7788162 | F24: ='S3'!B24 -> 2.1710526 | G24: ='S4'!B24 -> 1.0876321 | H24: ='S5'!B24 -> 1.9444444
B25: =SSum!U1 -> Eave Height | C25: =SSum!U3 -> 18 | D25: ='S1'!B26 -> 20 | E25: ='S2'!B26 -> 18 | F25: ='S3'!B26 -> 18 | G25: ='S4'!B26 -> 21 | H25: ='S5'!B26 -> 18
B26: =SSum!Z1 -> Loading | C26: =SSum!Z3 -> 0 GL/3 DH | D26: ='S1'!B27 -> 1 GL/3 DH | E26: ='S2'!B27 -> 1 GL/2 DH | F26: ='S3'!B27 -> 3 GL/1 DH | G26: ='S4'!B27 -> 1 GL/2 DH | H26: ='S5'!B27 -> 3 GL/2 DH
B27: =SSum!AA1 -> Loading SF | C27: =SSum!AA3 -> 5422.6667 | D27: =SSum!AA6 -> 4903.5 | E27: =SSum!AA7 -> 4280 | F27: =SSum!AA8 -> 3800 | G27: =SSum!AA9 -> 4290.6667 | H27: =SSum!AA10 -> 2880
B28: =SSum!AB1 -> Other | C28: =SSum!AB3 -> None | D28: =SSum!$AB6 -> None | E28: =SSum!$AB7 -> None | F28: =SSum!$AB8 -> None | G28: =SSum!$AB9 -> Ancillary Bldg. | H28: =SSum!$AB10 -> None
C31: Subject | D31: =D1 -> Sale 1 | E31: =E1 -> Sale 2 | F31: =F1 -> Sale 3 | G31: =G1 -> Sale 4 | H31: =H1 -> Sale 5
B32: Address | C32: =C3 -> 4735 Dwight Evans Rd | D32: =D3 -> 10725 John Price Rd | E32: =E3 -> 1508 Industrial Dr | F32: =F3 -> 138 Cedar Pointe Dr | G32: =G3 -> 227 Old Hebron St | H32: =H3 -> 1020 Forsyth Ave
C33: =C4 -> Charlotte, NC | D33: =D4 -> Charlotte, NC | E33: =E4 -> Matthews, NC | F33: =F4 -> Mooresville, NC | G33: =G4 -> Charlotte, NC | H33: =H4 -> Indian Trail, NC
B34: Sale Price | D34: =D8 -> 2275000 | E34: =E8 -> 1845000 | F34: =F8 -> 1575000 | G34: =G8 -> 1725000 | H34: =H8 -> 1775000
B35: Gross Building Area (SF) | C35: =C16 -> 16268 | D35: =D16 -> 19614 | E35: =E16 -> 12840 | F35: =F16 -> 15200 | G35: =G16 -> 12872 | H35: =H16 -> 14400
B36: Price/SF | D36: =D9 -> 115.98858 | E36: =E9 -> 143.69159 | F36: =F9 -> 103.61842 | G36: =G9 -> 134.01181 | H36: =H9 -> 123.26389
B37: Transactional Adjustments
B38: Property Rights | D38: =D12 -> Leased Fee | E38: =E12 -> Fee Simple | F38: =F12 -> Fee Simple | G38: =G12 -> Fee Simple | H38: =H12 -> Leased Fee
B39: Adjustment | D39: 0 | E39: 0 | F39: 0 | G39: 0 | H39: 0
B40: Adjusted Sale Price/SF | D40: =IF(D39<>0,(D36*(1+D39)),(D36)) -> 115.98858 | E40: =IF(E39<>0,(E36*(1+E39)),(E36)) -> 143.69159 | F40: =IF(F39<>0,(F36*(1+F39)),(F36)) -> 103.61842 | G40: =IF(G39<>0,(G36*(1+G39)),(G36)) -> 134.01181 | H40: =IF(H39<>0,(H36*(1+H39)),(H36)) -> 123.26389
B41: Cash Equivalency | D41: Assumed Market | E41: Assumed Market | F41: Assumed Market | G41: Assumed Market | H41: Assumed Market
B42: Adjustment | D42: 0 | E42: 0 | F42: 0 | G42: 0 | H42: 0
...

Sheet RSum
A1: Sale | B1: Address | C1: City, State | D1: Parcel No.(s) | E1: Tenant | F1: Lease Type | G1: Lease Date | H1: Lease Term | I1: Lease Rate (S/SF/Yr) | J1: Property Rights Conveyed | K1: Expense Structure | L1: Verification | M1: Rentable Building Area (SF) | N1: Building Size (SF) | O1: Year Built | P1: Office (SF) | Q1: Finished Ratio | R1: Quality | S1: Effective Age/Condition | T1: Eave Height | U1: =Subj.!B58 -> Access | V1: Parking Spaces | W1: Parking Ratio | X1: Building Use | Y1: Loading | Z1: Loading SF | AA1: Other | AB1: Zoning | AC1: Comments | AD1: Notes
A3: Subject | B3: =Subj.!D8 -> 4735 Dwight Evans Rd | C3: =Subj.!D9 -> Charlotte, NC | D3: =Subj.!D11 -> 145-301-22 | M3: =Subj.!D38 -> 16268 | O3: =Subj.!D36 -> 1989 | P3: =Subj.!D41 -> 1209 | Q3: =P3/M3 -> 0.074317679 | R3: =Subj.!D35 -> Average | S3: =Subj.!D54 -> 10 | T3: =Subj.!D44 -> 18 | U3: =Subj.!D58 -> Good | V3: =Subj.!D50 -> 53 | W3: =Subj.!D51 -> 0.91727241 | X3: Industrial | Y3: =Subj.!D47 -> 0 GL/3 DH | Z3: =M3/3 -> 5422.6667 | AA3: =Subj.!D59 -> None | AB3: =Subj.!D28 -> I-2
B6: 647 Michael Wylie Dr | C6: Charlotte, NC | D6: 145-271-21 | E6: Renner | F6: Direct | G6: 44409 | H6: 120 | I6: 11.24 | J6: Typical | K6: NNN | L6: Listing Broker | M6: 18090 | N6: 18090 | O6: 1982 | P6: 1980 | Q6: =P6/M6 -> 0.10945274 | R6: Good | S6: 5 | T6: 15 | U6: Good | V6: 17 | W6: =V6/(N6/1000) -> 0.93974572 | X6: Industrial | Y6: 2 GL/2 DH | Z6: =M6/4 -> 4522.5 | AA6: None | AC6: This reflects the effective rent for space in an 18,090-square-foot, freestanding just north of the Interstate 77/Billy Graham Parkway interchange within the city limits of Charlotte in Mecklenburg County, North Carolina. The building is demised into 1,980 square feet of office space and 16,110 square feet of warehouse space. The ten-year, triple-net lease was executed with a starting rent of $9.95 per square foot per year having yearly escalations of 3 percent with one month free rent and a reported tenant improvement allowance of $1.00 per square foot.
B7: 3300 Oak Lake Blvd | C7: Charlotte, NC | D7: 143-261-05 | E7: Zoe Baby Products | F7: Direct | G7: 44256 | H7: 72 | I7: 8.51 | J7: Typical | K7: NNN | L7: Listing Broker | M7: 16492 | N7: 16492 | O7: 1998 | P7: 1484 | Q7: =P7/M7 -> 0.089983022 | R7: Good | S7: 7 | T7: 16 | U7: Good | V7: 9 | W7: =V7/(N7/1000) -> 0.54571914 | X7: Industrial | Y7: 1 GL/1 DH | Z7: =M7/2 -> 8246 | AA7: None | AC7: This reflects the effective rent for space in a 16,492-square-foot, freestanding industrial building located just east of the Billy Graham Parkway/West Tyvola Road interchange with the city limits of Charlotte in Mecklenburg County, North Carolina. The building is fully-conditioned and has approximately 1,484 square feet of office space. The triple-net lease was executed turn-key with a starting rent of $7.89 per square foot per year having 3.0 percent yearly escalations.
B8: 2732 Interstate St, Ste F | C8: Charlotte, NC | D8: 061-123-12 | E8: Confidential | F8: Direct | G8: 44348 | H8: 36 | I8: 9.76 | J8: Typical | K8: NNN | L8: Listing Broker | M8: 3628 | N8: 26040 | O8: 1983 | P8: 1200 | Q8: =P8/M8 -> 0.33076075 | R8: Good | S8: 10 | T8: 16 | U8: Good | V8: 55 | W8: =V8/(N8/1000) -> 2.1121352 | X8: Industrial | Y8: 0 GL/1 DH | Z8: =M8/1 -> 3628 | AA8: None | AC8: This reflects the effective rent for space in a 26,040-square-foot, multi-tenant industrial building located in the Airport 85 Business Park just east of the Billy Graham Parkway/Interstate 85 interchange within the city limits of Charlotte in Mecklenburg County, North Carolina. The unit has approximately 1,200 square feet of office space and one dock-high door. The triple-net lease was executed turn-key with a starting rent of $9.75 per square foot per year and no escalations. The space was on the market for about 10 months with an asking rental rate of $10.00 per square foot.
B9: 201 Southside Dr | C9: Charlotte, NC | D9: 149-031-05 | E9: J&B Construction | F9: Direct | G9: 44013 | H9: 60 | I9: 9.36 | J9: Typical | K9: NNN | L9: Listing Broker | M9: 13700 | N9: 13700 | O9: 1967 | P9: 3151 | Q9: =P9/M9 -> 0.23 | R9: Average | S9: 10 | T9: 16 | U9: Good | V9: 9 | W9: =V9/(N9/1000) -> 0.65693431 | X9: Industrial | Y9: 0 GL/2 DH | Z9: =M9/2 -> 6850 | AA9: None | AC9: This reflects the effective rent for space in a 13,700-square-foot, freestanding industrial building located just northeast of the Billy Graham Parkway/Interstate 77 interchange with the city limits of Charlotte in Mecklenburg County, North Carolina. The building is demised into 3,151 square feet of office space and 10,549 square feet of warehouse space with two dock-high doors. The triple-net lease was executed turn-key with a starting rent of $9.36 per square foot per year and no escalations.
I19: 7.89
I20: =I19*1.03 -> 8.1267
I21: =I20*1.03 -> 8.370501
I22: =I21*1.03 -> 8.621616
I23: =I22*1.03 -> 8.8802645
I24: =I23*1.03 -> 9.1466724
I26: =SUM(I19:I24)/6 -> 8.505959
I29: 9.95 | J29: =I29*18090 -> 179995.5
I30: =I29*1.03 -> 10.2485 | J30: =I30*18090 -> 185395.36
I31: =I30*1.03 -> 10.555955 | J31: =I31*18090 -> 190957.23
I32: =I31*1.03 -> 10.872634 | J32: =I32*18090 -> 196685.94
I33: =I32*1.03 -> 11.198813 | J33: =I33*18090 -> 202586.52
I34: =I33*1.03 -> 11.534777
I35: =I34*1.03 -> 11.88082
I36: =I35*1.03 -> 12.237245
I37: =I36*1.03 -> 12.604362
I38: =I37*1.03 -> 12.982493
I40: =SUM(I29:I38) -> 114.0656 | J40: =(SUM(J29:J33)-18080-15000)/5 -> 184508.11
J43: {=sum} -> #NAME?

Sheet R1
A1: Comparable Rental 1 | B1: =RG!#REF! -> #REF!
A2: Location Details
A3: =RSum!B1 -> Address | B3: =RSum!B6 -> 647 Michael Wylie Dr
B4: =RSum!C6 -> Charlotte, NC
A5: =RSum!D1 -> Parcel No.(s) | B5: =RSum!D6 -> 145-271-21
A6: Transaction Data
A7: =RSum!J1 -> Property Rights Conveyed | B7: =RSum!J6 -> Typical
A8: =RSum!E1 -> Tenant | B8: =RSum!E6 -> Renner
A9: =RSum!F1 -> Lease Type | B9: =RSum!F6 -> Direct
A10: =RSum!G1 -> Lease Date | B10: =RSum!G6 -> 44409
A11: =RSum!H1 -> Lease Term | B11: =RSum!H6 -> 120
A12: =RSum!I1 -> Lease Rate (S/SF/Yr) | B12: =RSum!I6 -> 11.24
A13: =RSum!K1 -> Expense Structure | B13: =RSum!K6 -> NNN
A14: =RSum!L1 -> Verification | B14: =RSum!L6 -> Listing Broker
A15: Physical Attributes
A16: =RSum!M1 -> Rentable Building Area (SF) | B16: =RSum!M6 -> 18090
A17: =RSum!O1 -> Year Built | B17: =RSum!O6 -> 1982
A18: =RSum!R1 -> Quality | B18: =RSum!R6 -> Good
A19: =RSum!S1 -> Effective Age/Condition | B19: =RSum!S6 -> 5
A20: =RSum!Q1 -> Finished Ratio | B20: =RSum!Q6 -> 0.10945274
A21: =RSum!U1 -> Access | B21: =RSum!U6 -> Good
A22: =RSum!W1 -> Parking Ratio | B22: =RSum!W6 -> 0.93974572
A23: =RSum!T1 -> Eave Height | B23: =RSum!T6 -> 15
A24: =RSum!Y1 -> Loading | B24: =RSum!Y6 -> 2 GL/2 DH
A25: =RSum!Z1 -> Loading SF | B25: =RSum!Z6 -> 4522.5
A26: =RSum!X1 -> Building Use | B26: =RSum!X6 -> Industrial
A27: =RSum!AA1 -> Other | B27: =RSum!AA6 -> None
A28: Comments
A29: =RSum!AC6 -> This reflects the effective rent for space in an 18,090-square-foot, freestanding just north of the Interstate 77/Billy Graham Parkway interchange within the city limits of Charlotte in Mecklenburg County, North Carolina. The building is demised into 1,980 square feet of office space and 16,110 square feet of warehouse space. The ten-year, triple-net lease was executed with a starting rent of $9.95 per square foot per year having yearly escalations of 3 percent with one month free rent and a reported tenant improvement allowance of $1.00 per square foot. | B29: #REF!

Sheet R2
A1: Comparable Rental 2
A2: Location Details
A3: =RSum!B1 -> Address | B3: =RSum!B7 -> 3300 Oak Lake Blvd
B4: =RSum!C7 -> Charlotte, NC
A5: =RSum!D1 -> Parcel No.(s) | B5: =RSum!D7 -> 143-261-05
A6: Transaction Data
A7: =RSum!J1 -> Property Rights Conveyed | B7: =RSum!J7 -> Typical
A8: =RSum!E1 -> Tenant | B8: =RSum!E7 -> Zoe Baby Products
A9: =RSum!F1 -> Lease Type | B9: =RSum!F7 -> Direct
A10: =RSum!G1 -> Lease Date | B10: =RSum!G7 -> 44256
A11: =RSum!H1 -> Lease Term | B11: =RSum!H7 -> 72
A12: =RSum!I1 -> Lease Rate (S/SF/Yr) | B12: =RSum!I7 -> 8.51
A13: =RSum!K1 -> Expense Structure | B13: =RSum!K7 -> NNN
A14: =RSum!L1 -> Verification | B14: =RSum!L7 -> Listing Broker
A15: Physical Attributes
A16: =RSum!M1 -> Rentable Building Area (SF) | B16: =RSum!M7 -> 16492
A17: =RSum!O1 -> Year Built | B17: =RSum!O7 -> 1998
A18: =RSum!R1 -> Quality | B18: =RSum!R7 -> Good
A19: =RSum!S1 -> Effective Age/Condition | B19: =RSum!S7 -> 7
A20: =RSum!Q1 -> Finished Ratio | B20: =RSum!Q7 -> 0.089983022
A21: =RSum!U1 -> Access | B21: =RSum!U7 -> Good
A22: =RSum!W1 -> Parking Ratio | B22: =RSum!W7 -> 0.54571914
A23: =RSum!T1 -> Eave Height | B23: =RSum!T7 -> 16
A24: =RSum!Y1 -> Loading | B24: =RSum!Y7 -> 1 GL/1 DH
A25: =RSum!Z1 -> Loading SF | B25: =RSum!Z7 -> 8246
A26: =RSum!X1 -> Building Use | B26: =RSum!X7 -> Industrial
A27: =RSum!AA1 -> Other | B27: =RSum!AA7 -> None
A28: Comments
A29: =RSum!AC7 -> This reflects the effective rent for space in a 16,492-square-foot, freestanding industrial building located just east of the Billy Graham Parkway/West Tyvola Road interchange with the city limits of Charlotte in Mecklenburg County, North Carolina. The building is fully-conditioned and has approximately 1,484 square feet of office space. The triple-net lease was executed turn-key with a starting rent of $7.89 per square foot per year having 3.0 percent yearly escalations.

Sheet R3
A1: Comparable Rental 3 | B1: =RG!#REF! -> #REF!
A2: Location Details
A3: =RSum!B1 -> Address | B3: =RSum!B8 -> 2732 Interstate St, Ste F
B4: =RSum!C8 -> Charlotte, NC
A5: =RSum!D1 -> Parcel No.(s) | B5: =RSum!D8 -> 061-123-12
A6: Transaction Data
A7: =RSum!J1 -> Property Rights Conveyed | B7: =RSum!J8 -> Typical
A8: =RSum!E1 -> Tenant | B8: =RSum!E8 -> Confidential
A9: =RSum!F1 -> Lease Type | B9: =RSum!F8 -> Direct
A10: =RSum!G1 -> Lease Date | B10: =RSum!G8 -> 44348
A11: =RSum!H1 -> Lease Term | B11: =RSum!H8 -> 36
A12: =RSum!I1 -> Lease Rate (S/SF/Yr) | B12: =RSum!I8 -> 9.76
A13: =RSum!K1 -> Expense Structure | B13: =RSum!K8 -> NNN
A14: =RSum!L1 -> Verification | B14: =RSum!L8 -> Listing Broker
A15: Physical Attributes
A16: =RSum!M1 -> Rentable Building Area (SF) | B16: =RSum!M8 -> 3628
A17: =RSum!O1 -> Year Built | B17: =RSum!O8 -> 1983
A18: =RSum!R1 -> Quality | B18: =RSum!R8 -> Good
A19: =RSum!S1 -> Effective Age/Condition | B19: =RSum!S8 -> 10
A20: =RSum!Q1 -> Finished Ratio | B20: =RSum!Q8 -> 0.33076075
A21: =RSum!U1 -> Access | B21: =RSum!U8 -> Good
A22: =RSum!W1 -> Parking Ratio | B22: =RSum!W8 -> 2.1121352
A23: =RSum!T1 -> Eave Height | B23: =RSum!T8 -> 16
A24: =RSum!Y1 -> Loading | B24: =RSum!Y8 -> 0 GL/1 DH
A25: =RSum!Z1 -> Loading SF | B25: =RSum!Z8 -> 3628
A26: =RSum!X1 -> Building Use | B26: =RSum!X8 -> Industrial
A27: =RSum!AA1 -> Other | B27: =RSum!AA8 -> None
A28: Comments
A29: =RSum!AC8 -> This reflects the effective rent for space in a 26,040-square-foot, multi-tenant industrial building located in the Airport 85 Business Park just east of the Billy Graham Parkway/Interstate 85 interchange within the city limits of Charlotte in Mecklenburg County, North Carolina. The unit has approximately 1,200 square feet of office space and one dock-high door. The triple-net lease was executed turn-key with a starting rent of $9.75 per square foot per year and no escalations. The space was on the market for about 10 months with an asking rental rate of $10.00 per square foot.

Sheet R4
A1: Comparable Rental 4 | B1: =RG!#REF! -> #REF!
A2: Location Details
A3: =RSum!B1 -> Address | B3: =RSum!B9 -> 201 Southside Dr
B4: =RSum!C9 -> Charlotte, NC
A5: =RSum!D1 -> Parcel No.(s) | B5: =RSum!D9 -> 149-031-05
A6: Transaction Data
A7: =RSum!J1 -> Property Rights Conveyed | B7: =RSum!J9 -> Typical
A8: =RSum!E1 -> Tenant | B8: =RSum!E9 -> J&B Construction
A9: =RSum!F1 -> Lease Type | B9: =RSum!F9 -> Direct
A10: =RSum!G1 -> Lease Date | B10: =RSum!G9 -> 44013
A11: =RSum!H1 -> Lease Term | B11: =RSum!H9 -> 60
A12: =RSum!I1 -> Lease Rate (S/SF/Yr) | B12: =RSum!I9 -> 9.36
A13: =RSum!K1 -> Expense Structure | B13: =RSum!K9 -> NNN
A14: =RSum!L1 -> Verification | B14: =RSum!L9 -> Listing Broker
A15: Physical Attributes
A16: =RSum!M1 -> Rentable Building Area (SF) | B16: =RSum!M9 -> 13700
A17: =RSum!O1 -> Year Built | B17: =RSum!O9 -> 1967
A18: =RSum!R1 -> Quality | B18: =RSum!R9 -> Average
A19: =RSum!S1 -> Effective Age/Condition | B19: =RSum!S9 -> 10
A20: =RSum!Q1 -> Finished Ratio | B20: =RSum!Q9 -> 0.23
A21: =RSum!U1 -> Access | B21: =RSum!U9 -> Good
A22: =RSum!W1 -> Parking Ratio | B22: =RSum!W9 -> 0.65693431
A23: =RSum!T1 -> Eave Height | B23: =RSum!T9 -> 16
A24: =RSum!Y1 -> Loading | B24: =RSum!Y9 -> 0 GL/2 DH
A25: =RSum!Z1 -> Loading SF | B25: =RSum!Z9 -> 6850
A26: =RSum!X1 -> Building Use | B26: =RSum!X9 -> Industrial
A27: =RSum!AA1 -> Other | B27: =RSum!AA9 -> None
A28: Comments
A29: =RSum!AC9 -> This reflects the effective rent for space in a 13,700-square-foot, freestanding industrial building located just northeast of the Billy Graham Parkway/Interstate 77 interchange with the city limits of Charlotte in Mecklenburg County, North Carolina. The building is demised into 3,151 square feet of office space and 10,549 square feet of warehouse space with two dock-high doors. The triple-net lease was executed turn-key with a starting rent of $9.36 per square foot per year and no escalations.

Sheet RAdj
A2: Row Height: 17
A4: Subject | B4: =RG!C31 -> 16268 | E4: =RSum!M1 -> Rentable Building Area (SF) | F4: Difference (SF) | G4: Applied Adjustment
A5: Base | B5: -0.1 | D5: Rental 1 | E5: =RG!D31 -> 18090 | F5: =ABS(E5-$B$4) -> 1822 | G5: =F5/F9*B5*-1 -> 0.014414557
D6: Rental 2 | E6: =RG!E31 -> 16492 | F6: =ABS(E6-$B$4) -> 224 | G6: =F6/F9*B5*-1 -> 0.0017721519
D7: Subject | E7: =RG!C31 -> 16268 | F7: - | G7: -
D8: Rental 4 | E8: =RG!G31 -> 13700 | F8: =ABS(E8-$B$4) -> 2568 | G8: =F8/F9*B5 -> -0.020316456
D9: Rental 3 | E9: =RG!F31 -> 3628 | F9: =ABS(E9-$B$4) -> 12640 | G9: =B5 -> -0.1

Sheet RG
C1: Subject | D1: Rental 1 | E1: Rental 2 | F1: Rental 3 | G1: Rental 4
B2: Location Details
B3: Address | C3: =RSum!B3 -> 4735 Dwight Evans Rd | D3: ='R1'!B3 -> 647 Michael Wylie Dr | E3: ='R2'!B3 -> 3300 Oak Lake Blvd | F3: ='R3'!B3 -> 2732 Interstate St, Ste F | G3: ='R4'!B3 -> 201 Southside Dr
C4: =RSum!C3 -> Charlotte, NC | D4: ='R1'!B4 -> Charlotte, NC | E4: ='R2'!B4 -> Charlotte, NC | F4: ='R3'!B4 -> Charlotte, NC | G4: ='R4'!B4 -> Charlotte, NC
B5: Parcel No.(s) | C5: =RSum!D3 -> 145-301-22 | D5: ='R1'!B5 -> 145-271-21 | E5: ='R2'!B5 -> 143-261-05 | F5: ='R3'!B5 -> 061-123-12 | G5: ='R4'!B5 -> 149-031-05
B6: Transaction Data
B7: =RSum!E1 -> Tenant | D7: ='R1'!B8 -> Renner | E7: ='R2'!B8 -> Zoe Baby Products | F7: ='R3'!B8 -> Confidential | G7: ='R4'!B8 -> J&B Construction
B8: =RSum!F1 -> Lease Type | D8: ='R1'!B9 -> Direct | E8: ='R2'!B9 -> Direct | F8: ='R3'!B9 -> Direct | G8: ='R4'!B9 -> Direct
B9: =RSum!G1 -> Lease Date | D9: ='R1'!B10 -> 44409 | E9: ='R2'!B10 -> 44256 | F9: ='R3'!B10 -> 44348 | G9: ='R4'!B10 -> 44013
B10: =RSum!H1 -> Lease Term | D10: ='R1'!B11 -> 120 | E10: ='R2'!B11 -> 72 | F10: ='R3'!B11 -> 36 | G10: ='R4'!B11 -> 60
B11: =RSum!I1 -> Lease Rate (S/SF/Yr) | D11: ='R1'!B12 -> 11.24 | E11: ='R2'!B12 -> 8.51 | F11: ='R3'!B12 -> 9.76 | G11: ='R4'!B12 -> 9.36
B12: =RSum!K1 -> Expense Structure | D12: ='R1'!B13 -> NNN | E12: ='R2'!B13 -> NNN | F12: ='R3'!B13 -> NNN | G12: ='R4'!B13 -> NNN
B13: Physical Attributes
B14: =RSum!M1 -> Rentable Building Area (SF) | C14: =RSum!M3 -> 16268 | D14: ='R1'!B16 -> 18090 | E14: ='R2'!B16 -> 16492 | F14: ='R3'!B16 -> 3628 | G14: ='R4'!B16 -> 13700
B15: =RSum!O1 -> Year Built | C15: =RSum!O3 -> 1989 | D15: ='R1'!B17 -> 1982 | E15: ='R2'!B17 -> 1998 | F15: ='R3'!B17 -> 1983 | G15: ='R4'!B17 -> 1967
B16: =RSum!R1 -> Quality | C16: =RSum!R3 -> Average | D16: ='R1'!B18 -> Good | E16: ='R2'!B18 -> Good | F16: ='R3'!B18 -> Good | G16: ='R4'!B18 -> Average
B17: =RSum!S1 -> Effective Age/Condition | C17: =RSum!S3 -> 10 | D17: ='R1'!B19 -> 5 | E17: ='R2'!B19 -> 7 | F17: ='R3'!B19 -> 10 | G17: ='R4'!B19 -> 10
B18: =RSum!U1 -> Access | C18: =RSum!U3 -> Good | D18: ='R1'!B21 -> Good | E18: ='R2'!B21 -> Good | F18: ='R3'!B21 -> Good | G18: ='R4'!B21 -> Good
B19: =RSum!Q1 -> Finished Ratio | C19: =RSum!Q3 -> 0.074317679 | D19: =RSum!Q6 -> 0.10945274 | E19: =RSum!Q7 -> 0.089983022 | F19: =RSum!Q8 -> 0.33076075 | G19: =RSum!Q9 -> 0.23
B20: =RSum!W1 -> Parking Ratio | C20: =RSum!W3 -> 0.91727241 | D20: ='R1'!B22 -> 0.93974572 | E20: ='R2'!B22 -> 0.54571914 | F20: ='R3'!B22 -> 2.1121352 | G20: ='R4'!B22 -> 0.65693431
B21: =RSum!T1 -> Eave Height | C21: =RSum!T3 -> 18 | D21: =RSum!T6 -> 15 | E21: =RSum!T7 -> 16 | F21: =RSum!T8 -> 16 | G21: =RSum!T9 -> 16
B22: =RSum!Y1 -> Loading | C22: =RSum!Y3 -> 0 GL/3 DH | D22: =RSum!Y6 -> 2 GL/2 DH | E22: =RSum!Y7 -> 1 GL/1 DH | F22: =RSum!Y8 -> 0 GL/1 DH | G22: =RSum!Y9 -> 0 GL/2 DH
B23: =RSum!Z1 -> Loading SF | C23: =RSum!Z3 -> 5422.6667 | D23: =RSum!Z6 -> 4522.5 | E23: =RSum!Z7 -> 8246 | F23: =RSum!Z8 -> 3628 | G23: =RSum!Z9 -> 6850
B24: =RSum!X1 -> Building Use | C24: =RSum!X3 -> Industrial | D24: ='R1'!B26 -> Industrial | E24: ='R2'!B26 -> Industrial | F24: ='R3'!B26 -> Industrial | G24: ='R4'!B26 -> Industrial
B25: =RSum!AA1 -> Other | C25: =RSum!AA3 -> None | D25: ='R1'!B27 -> None | E25: ='R2'!B27 -> None | F25: ='R3'!B27 -> None | G25: ='R4'!B27 -> None
C28: Subject | D28: =D1 -> Rental 1 | E28: =E1 -> Rental 2 | F28: =F1 -> Rental 3 | G28: =G1 -> Rental 4
B29: Address | C29: =C3 -> 4735 Dwight Evans Rd | D29: =D3 -> 647 Michael Wylie Dr | E29: =E3 -> 3300 Oak Lake Blvd | F29: =F3 -> 2732 Interstate St, Ste F | G29: =G3 -> 201 Southside Dr
C30: =C4 -> Charlotte, NC | D30: =D4 -> Charlotte, NC | E30: =E4 -> Charlotte, NC | F30: =F4 -> Charlotte, NC | G30: =G4 -> Charlotte, NC
B31: =B14 -> Rentable Building Area (SF) | C31: =C14 -> 16268 | D31: =D14 -> 18090 | E31: =E14 -> 16492 | F31: =F14 -> 3628 | G31: =G14 -> 13700
B32: =B11 -> Lease Rate (S/SF/Yr) | D32: =D11 -> 11.24 | E32: =E11 -> 8.51 | F32: =F11 -> 9.76 | G32: =G11 -> 9.36
B33: Transactional Adjustments
B34: =RSum!J1 -> Property Rights Conveyed | D34: ='R1'!B7 -> Typical | E34: ='R2'!B7 -> Typical | F34: ='R3'!B7 -> Typical | G34: ='R4'!B7 -> Typical
B35: Adjustment | D35: 0 | E35: 0 | F35: 0 | G35: 0
B36: Adjusted Rent/SF/Yr | D36: =IF(D35<>0,D32+D35,D32) -> 11.24 | E36: =IF(E35<>0,E32+E35,E32) -> 8.51 | F36: =IF(F35<>0,F32+F35,F32) -> 9.76 | G36: =IF(G35<>0,G32+G35,G32) -> 9.36
B37: Lease Structure | D37: =D12 -> NNN | E37: =E12 -> NNN | F37: =F12 -> NNN | G37: =G12 -> NNN
B38: Adjustment | D38: 0 | E38: 0 | F38: 0 | G38: 0
B39: =B36 -> Adjusted Rent/SF/Yr | D39: =IF(D38<>0,D36+D38,D36) -> 11.24 | E39: =IF(E38<>0,E36+E38,E36) -> 8.51 | F39: =IF(F38<>0,F36+F38,F36) -> 9.76 | G39: =IF(G38<>0,G36+G38,G36) -> 9.36
B40: Conditions of Lease | D40: 10-year term | E40: None | F40: None | G40: None
B41: Adjustment | D41: -1.04 | E41: 0 | F41: 0 | G41: 0
B42: =B36 -> Adjusted Rent/SF/Yr | D42: =IF(D41<>0,D39+D41,D39) -> 10.2 | E42: =IF(E41<>0,E39+E41,E39) -> 8.51 | F42: =IF(F41<>0,F39+F41,F39) -> 9.76 | G42: =IF(G41<>0,G39+G41,G39) -> 9.36
...

Sheet BOI
B2: Income Pro Forma | H2: Band of Investment Assumptions
B3: Revenue | H3: Mortgage Interest Rate | I3: 0.0425 | L3: Mortgage-Equity Capitalization Rate | V3: Mortgage Ratio | W3: Mortgage Constant | X3: Debt Coverage Ratio | Y3: Indicated Capitalization Rate
B4: Base Rent | F4: =RG!K62 -> 146412 | H4: Amortization Period | I4: 30 | J4: Years | L4: Mortgage Requirement | M4: =I5 -> 0.75 | N4: X | O4: =I6 -> 0.059032787 | P4: = | R4: =M4*O4 -> 0.04427459 | V4: =I5 -> 0.75 | W4: =I6 -> 0.059032787 | X4: 1.5 | Y4: =V4*W4*X4 -> 0.066411885
B5: Other Income | F5: 0 | H5: Mortgage Ratio (Loan-to-Value) | I5: 0.75 | L5: Equity Requirement | M5: =1-M4 -> 0.25 | N5: X | O5: =I7 -> 0.12 | P5: = | R5: =M5*O5 -> 0.03
B6: Reimbursements | F6: 0 | H6: Mortgage Constant | I6: =PMT((I3/12),(I4*12),-1,0,0)*12 -> 0.059032787 | L6: Indicated Capitalization Rate | R6: =SUM(R4:R5) -> 0.07427459
B7: Potential Gross Income | F7: =SUM(F4:F6) -> 146412 | H7: Equity Dividend Rate | I7: 0.12
B8: Vacancy and Collection Loss | C8: 0.04 | F8: =F7*(-1*C8) -> -5856.48 | H8: Holding Period | I8: 10 | J8: Years
B9: Effective Gross Income | F9: =SUM(F7:F8) -> 140555.52
B10: Expenses
B11: Property Management | C11: 0.02 | D11: =F9*C11 -> 2811.1104
B12: Reserves | C12: 0.02 | D12: =F9*C12 -> 2811.1104 | L12: Mortgage-Equity Capitalization Rate
B13: Total Expenses | F13: =SUM(D11:D12)*-1 -> -5622.2208 | L13: Mortgage Requirement | M13: =I5 -> 0.75 | N13: X | O13: =I6 -> 0.059032787 | R13: = | T13: =M13*O13 -> 0.04427459
B14: Net Operating Income | F14: =SUM(F9:F13) -> 134933.3 | L14: Equity Requirement | M14: =1-M13 -> 0.25 | N14: X | O14: =I7 -> 0.12 | R14: = | T14: =M14*O14 -> 0.03
L15: Debt Reduction | M15: =I5 -> 0.75 | N15: X | O15: =CUMPRINC((I3/12),(I4*12),1,1,(I8*12),0) -> -0.20556766 | P15: X | Q15: =PMT(I7,I8,0,1,0)*-1 -> 0.056984164 | R15: = | T15: =M15*O15*Q15 -> -0.0087855758
C16: PSF | L16: Indicated Capitalization Rate | T16: =SUM(T13:T15) -> 0.065489014
B17: Property Management | C17: =D11/Subj.!D37 -> 0.1728
B18: Reserves | C18: =D12/Subj.!D37 -> 0.1728 | O18: =CUMPRINC((I3/12),(I4*12),1,1,(I8*12),0) -> -0.20556766 | P18: debt reduction
O19: =PMT(I7,I8,0,1,0) -> -0.056984164 | P19: SFF
L21: Adjustment for Change in Value
L22: Appreciation/Depreciation | O22: 0.02
L23: Times SFF | O23: =O19 -> -0.056984164
L24: Adjustment Factor | O24: =O22*O23 -> -0.0011396833
L26: Adjusted Rate | O26: =T16+O24 -> 0.064349331

Sheet Cap Sales
A1: =AVERAGE(J6:J21) -> 0.0691875 | B1: Average
A2: =MEDIAN(J6:J21) -> 0.07125 | B2: Median
A3: =MIN(J6:J21) -> 0.05 | B3: Minimum
A4: =MAX(J6:J21) -> 0.086 | B4: Maximum
C5: Property Address | D5: Year Built | E5: Sale Date | F5: Sale Price | G5: Size - SF | H5: Price/SF | I5: NOI | J5: Cap Rate
C6: 4701 Granite Dr | D6: 1965 | E6: 44671 | F6: 4200000 | G6: 53382 | H6: =F6/G6 -> 78.678206 | I6: =F6*J6 -> 252000 | J6: 0.06
C7: Tucker, GA
C8: 122 Ethan Allen Dr | D8: 1987 | E8: 44559 | F8: 200000 | G8: 40000 | H8: =F8/G8 -> 5 | I8: =F8*J8 -> 16000 | J8: 0.08
C9: Dahlonega, GA
C10: 162 E Midland Ave | D10: 1975 | E10: 44531 | F10: 1525000 | G10: 42660 | H10: =F10/G10 -> 35.747773 | I10: =F10*J10 -> 106750 | J10: 0.07
C11: Winder, GA
C12: 1205 Hayes Industrial Dr | D12: 1981 | E12: 44396 | F12: 2800000 | G12: 29678 | H12: =F12/G12 -> 94.34598 | I12: =F12*J12 -> 140000 | J12: 0.05
C13: Marietta, GA
C14: 3630 Swiftwater Park Dr | D14: 2001 | E14: 44308 | F14: 2350000 | G14: 20000 | H14: =F14/G14 -> 117.5 | I14: =F14*J14 -> 170375 | J14: 0.0725
C15: Suwanee, GA
C16: 1420 Calvary Church Rd | D16: 1990 | E16: 44119 | F16: 1300000 | G16: 25440 | H16: =F16/G16 -> 51.100629 | I16: =F16*J16 -> 111800 | J16: 0.086
C17: Gainesville, GA
C18: 850 Mountain Industrial Dr | D18: 1979 | E18: 44117 | F18: 3840000 | G18: 42960 | H18: =F18/G18 -> 89.385475 | I18: =F18*J18 -> 288000 | J18: 0.075
C19: Marietta, GA
C20: 2171 Kingston Ct | D20: 1981 | E20: 44105 | F20: 5817000 | G20: 64144 | H20: =F20/G20 -> 90.68658 | I20: =F20*J20 -> 349020 | J20: 0.06
C21: Marietta, GA

Sheet Ins
B4: Replacement Cost Calculations
B6: Occupancy | C6: 406 Storage Warehouse
B7: Quality/Class | C7: Avg/C
B8: Building Size (SF) | C8: =Subj.!D37 -> 16268
D11: Units | E11: Unit Cost | F11: Total Cost
B12: Base Cost | D12: =C8 -> 16268 | E12: 42.7 | F12: =D12*E12 -> 694643.6
B13: Exterior Walls | D13: =C8 -> 16268 | E13: 18.83 | F13: =D13*E13 -> 306326.44
B14: Heating & Cooling | D14: =Subj.!D41 -> 1209 | E14: 7.04 | F14: =D14*E14 -> 8511.36
B15: Total Base Cost | D15: =C8 -> 16268 | E15: =F15/C8 -> 62.053196 | F15: =SUM(F12:F14) -> 1009481.4
B16: Insurance Exclusions | C16: 0.1 | F16: =-F15*C16 -> -100948.14
B17: Indicated Replacement Cost | F17: =SUM(F15:F16) -> 908533.26
B19: Rounded: | F19: 910000

Sheet Tax
C2: Parcel No(s). | D2: =Subj.!D11 -> 145-301-22
C3: Tax Year | D3: 2021
C4: Tax-Appraised Value:
C5: Land Value | D5: 0
C6: Improvement Value | D6: 1055600
C7: Accessory Value | D7: 0
C8: Total Tax-Appraised Value | D8: =D5+D6+D7 -> 1055600
C9: =D9*100 -> 100 | D9: 1
C10: Assessed Value | D10: =D8*D9 -> 1055600
C11: Times Millage Rate | D11: 0.00965
C12: Total Property Taxes | D12: =D10*D11 -> 10186.54

Sheet Final
I2: "As-Is"
B3: Market Value “As-Is” | F3: Market Value “As Is”
C4: Effective Date of Value | D4: Indicated Value | F4: Sales Comparison Approach | G4: =SG!L70 -> 1950000 | I4: ONE MILLION NINE HUNDRED FIFTY THOUSAND DOLLARS
I5: 1950000
B6: Sales Comparison Approach | C6: =Subj.!D61 -> 44747 | D6: =G4 -> 1950000 | F6: Income Capitalization Approach | G6: =RG!K80 -> 1930000
B8: Income Capitalization Approach | C8: =C6 -> 44747 | D8: =G6 -> 1930000 | I8: Prospective:
B10: Market Value Conclusion | C10: =C6 -> 44747 | D10: =I5 -> 1950000 | I10: ONE DOLLAR
I11: 1

Sheet AddC
B3: Development Schedule
B5: Project Costs | C5: 206476
B6: =E6 -> 15 | C6: =C5*(B6/100) -> 30971.4 | E6: 15
B7: Total Project Costs | C7: =SUM(C5:C6) -> 237447.4
B9: =E9 -> 10 | C9: =C7*(B9/100) -> 23744.74 | E9: 10
B10: Total Costs | C10: =C7+C9 -> 261192.14
B11: Rounded: | C11: 260000
B14: Stabilization/Lease-Up Costs
B15: Lease-Up Costs:
B16: Rent Loss $45,225 x 0.25 | C16: =E16*(F16/12) -> 11306.25 | E16: 45225 | F16: 3
B17: Tenant Improvement Allowance $0.00 psf | C17: 0
B18: Leasing Commissions $45.00 psf x 1,005 sf x 6% x 5 years | C18: =E18*G18*H18*F18 -> 13567.5 | E18: 45 | F18: 1005 | G18: 0.06 | H18: 5
B19: Total Leasing Costs: | C19: =SUM(C16:C18) -> 24873.75
B21: =E21 -> 15 | C21: =C19*E21 -> 373106.25 | E21: 15
B22: Total Costs | C22: =SUM(C19:C21) -> 397980
B23: Rounded: | C23: changed
